Traceback (most recent call last):
  File "/home/runner/micromamba/envs/docs/lib/python3.12/site-packages/jupyter_cache/executors/utils.py", line 58, in single_nb_execution
    executenb(
  File "/home/runner/micromamba/envs/docs/lib/python3.12/site-packages/nbclient/client.py", line 1319, in execute
    return NotebookClient(nb=nb, resources=resources, km=km, **kwargs).execute()
           ^^^^^^^^^^^^^^^^^^^^^^^^^^^^^^^^^^^^^^^^^^^^^^^^^^^^^^^^^^^^^^^^^^^^^
  File "/home/runner/micromamba/envs/docs/lib/python3.12/site-packages/jupyter_core/utils/__init__.py", line 165, in wrapped
    return loop.run_until_complete(inner)
           ^^^^^^^^^^^^^^^^^^^^^^^^^^^^^^
  File "/home/runner/micromamba/envs/docs/lib/python3.12/asyncio/base_events.py", line 691, in run_until_complete
    return future.result()
           ^^^^^^^^^^^^^^^
  File "/home/runner/micromamba/envs/docs/lib/python3.12/site-packages/nbclient/client.py", line 709, in async_execute
    await self.async_execute_cell(
  File "/home/runner/micromamba/envs/docs/lib/python3.12/site-packages/nbclient/client.py", line 1062, in async_execute_cell
    await self._check_raise_for_error(cell, cell_index, exec_reply)
  File "/home/runner/micromamba/envs/docs/lib/python3.12/site-packages/nbclient/client.py", line 918, in _check_raise_for_error
    raise CellExecutionError.from_cell_and_msg(cell, exec_reply_content)
nbclient.exceptions.CellExecutionError: An error occurred while executing the following cell:
------------------
platform = mm.Platform.getPlatformByName('OpenCL')
------------------


[0;31m---------------------------------------------------------------------------[0m
[0;31mOpenMMException[0m                           Traceback (most recent call last)
[0;32m/tmp/ipykernel_8090/3902948268.py[0m in [0;36m?[0;34m()[0m
[0;32m----> 1[0;31m [0mplatform[0m [0;34m=[0m [0mmm[0m[0;34m.[0m[0mPlatform[0m[0;34m.[0m[0mgetPlatformByName[0m[0;34m([0m[0;34m'OpenCL'[0m[0;34m)[0m[0;34m[0m[0;34m[0m[0m
[0m
[0;32m~/micromamba/envs/docs/lib/python3.12/site-packages/openmm/openmm.py[0m in [0;36m?[0;34m(name)[0m
[1;32m  12493[0m         [0mGet[0m [0mthe[0m [0mregistered[0m [0mPlatform[0m [0;32mwith[0m [0ma[0m [0mparticular[0m [0mname[0m[0;34m.[0m [0mIf[0m [0mno[0m [0mPlatform[0m [0;32mwith[0m [0mthat[0m [0mname[0m [0mhas[0m [0mbeen[0m [0mregistered[0m[0;34m,[0m [0mthis[0m [0mthrows[0m [0man[0m [0mexception[0m[0;34m.[0m[0;34m[0m[0;34m[0m[0m
[1;32m  12494[0m [0;34m[0m[0m
[1;32m  12495[0m         [0mThis[0m [0;32mis[0m [0midentical[0m [0mto[0m [0mthe[0m [0mversion[0m [0mof[0m [0mgetPlatform[0m[0;34m([0m[0;34m)[0m [0mthat[0m [0mtakes[0m [0ma[0m [0mname[0m[0;34m.[0m [0mIt[0m [0;32mis[0m [0mhere[0m [0;32mfor[0m [0mbackward[0m [0mcompatibility[0m[0;34m.[0m[0;34m[0m[0;34m[0m[0m
[1;32m  12496[0m         """
[0;32m> 12497[0;31m         [0;32mreturn[0m [0m_openmm[0m[0;34m.[0m[0mPlatform_getPlatformByName[0m[0;34m([0m[0mname[0m[0;34m)[0m[0;34m[0m[0;34m[0m[0m
[0m
[0;31mOpenMMException[0m: There is no registered Platform called "OpenCL"

